Workbook

Sheet RESUMEN 2026
A1: RESUMEN DE VENTAS 2026
A2: Cambio USD/GS utilizado: | B2: 6250
A3: Fuente: | B3: VENTAS TOTALES 2026 v2
A5: TOTALES GENERALES
A6: Total facturas emitidas | B6: =COUNTA('VENTAS TOTALES 2026 v2'!F2:F233) -> 232
A7: Facturas válidas (sin anulados) | B7: =COUNTIF('VENTAS TOTALES 2026 v2'!I2:I233,"<>N/A") -> 196
A8: Total ventas GS | B8: =SUMIF('VENTAS TOTALES 2026 v2'!I2:I233,"<>N/A",'VENTAS TOTALES 2026 v2'!D2:D233) -> 1260466450
A9: Total ventas USD (convertido a GS) | B9: =SUMIF('VENTAS TOTALES 2026 v2'!I2:I233,"<>N/A",'VENTAS TOTALES 2026 v2'!E2:E233)*B2 -> 326625000
A10: TOTAL GENERAL (GS) | B10: =B8+B9 -> 1587091450
A12: VENTAS POR MES
A13: MES | B13: VENTAS GS | C13: VENTAS USD (en GS) | D13: TOTAL (GS) | E13: % DEL TOTAL
A14: Enero 2026 | B14: {=SUMPRODUCT((TEXT('VENTAS TOTALES 2026 v2'!A2:A233,"MM")="01")*('VENTAS TOTALES 2026 v2'!I2:I233<>"N/A")*'VENTAS TOTALES 2026 v2'!D2:D233)} -> 120355000 | C14: {=SUMPRODUCT((TEXT('VENTAS TOTALES 2026 v2'!A2:A233,"MM")="01")*('VENTAS TOTALES 2026 v2'!I2:I233<>"N/A")*'VENTAS TOTALES 2026 v2'!E2:E233)*$B$2} -> 173837500 | D14: =B14+C14 -> 294192500 | E14: =IF($D$18=0,"",D14/$D$18) -> 0.2386077
A15: Febrero 2026 | B15: {=SUMPRODUCT((TEXT('VENTAS TOTALES 2026 v2'!A2:A233,"MM")="02")*('VENTAS TOTALES 2026 v2'!I2:I233<>"N/A")*'VENTAS TOTALES 2026 v2'!D2:D233)} -> 132426000 | C15: {=SUMPRODUCT((TEXT('VENTAS TOTALES 2026 v2'!A2:A233,"MM")="02")*('VENTAS TOTALES 2026 v2'!I2:I233<>"N/A")*'VENTAS TOTALES 2026 v2'!E2:E233)*$B$2} -> 42375000 | D15: =B15+C15 -> 174801000 | E15: =IF($D$18=0,"",D15/$D$18) -> 0.14177406
A16: Marzo 2026 | B16: {=SUMPRODUCT((TEXT('VENTAS TOTALES 2026 v2'!A2:A233,"MM")="03")*('VENTAS TOTALES 2026 v2'!I2:I233<>"N/A")*'VENTAS TOTALES 2026 v2'!D2:D233)} -> 386520500 | C16: {=SUMPRODUCT((TEXT('VENTAS TOTALES 2026 v2'!A2:A233,"MM")="03")*('VENTAS TOTALES 2026 v2'!I2:I233<>"N/A")*'VENTAS TOTALES 2026 v2'!E2:E233)*$B$2} -> 0 | D16: =B16+C16 -> 386520500 | E16: =IF($D$18=0,"",D16/$D$18) -> 0.31349123
A17: Abril 2026 | B17: {=SUMPRODUCT((TEXT('VENTAS TOTALES 2026 v2'!A2:A233,"MM")="04")*('VENTAS TOTALES 2026 v2'!I2:I233<>"N/A")*'VENTAS TOTALES 2026 v2'!D2:D233)} -> 335065750 | C17: {=SUMPRODUCT((TEXT('VENTAS TOTALES 2026 v2'!A2:A233,"MM")="04")*('VENTAS TOTALES 2026 v2'!I2:I233<>"N/A")*'VENTAS TOTALES 2026 v2'!E2:E233)*$B$2} -> 42375000 | D17: =B17+C17 -> 377440750 | E17: =IF($D$18=0,"",D17/$D$18) -> 0.30612701
A18: TOTAL | B18: =SUM(B14:B17) -> 974367250 | C18: =SUM(C14:C17) -> 258587500 | D18: =SUM(D14:D17) -> 1232954750 | E18: =SUM(E14:E17) -> 1
A20: VENTAS POR LÍNEA DE PRODUCTO
A21: LÍNEA | B21: VENTAS GS | C21: VENTAS USD (en GS) | D21: TOTAL (GS) | E21: % DEL TOTAL
A22: COMERCIAL | B22: {=SUMPRODUCT(('VENTAS TOTALES 2026 v2'!J2:J233="COMERCIAL")*'VENTAS TOTALES 2026 v2'!D2:D233)} -> 245635000 | C22: {=SUMPRODUCT(('VENTAS TOTALES 2026 v2'!J2:J233="COMERCIAL")*'VENTAS TOTALES 2026 v2'!E2:E233)*$B$2} -> 0 | D22: =B22+C22 -> 245635000 | E22: =IF($D$26=0,"",D22/$D$26) -> 0.15477054
A23: INDUSTRIAL | B23: {=SUMPRODUCT(('VENTAS TOTALES 2026 v2'!J2:J233="INDUSTRIAL")*'VENTAS TOTALES 2026 v2'!D2:D233)} -> 652679000 | C23: {=SUMPRODUCT(('VENTAS TOTALES 2026 v2'!J2:J233="INDUSTRIAL")*'VENTAS TOTALES 2026 v2'!E2:E233)*$B$2} -> 139937500 | D23: =B23+C23 -> 792616500 | E23: =IF($D$26=0,"",D23/$D$26) -> 0.49941451
A24: INSUMOS | B24: {=SUMPRODUCT(('VENTAS TOTALES 2026 v2'!J2:J233="INSUMOS")*'VENTAS TOTALES 2026 v2'!D2:D233)} -> 361562450 | C24: {=SUMPRODUCT(('VENTAS TOTALES 2026 v2'!J2:J233="INSUMOS")*'VENTAS TOTALES 2026 v2'!E2:E233)*$B$2} -> 186687500 | D24: =B24+C24 -> 548249950 | E24: =IF($D$26=0,"",D24/$D$26) -> 0.3454432
A25: ACCESORIOS | B25: {=SUMPRODUCT(('VENTAS TOTALES 2026 v2'!J2:J233="ACCESORIOS")*'VENTAS TOTALES 2026 v2'!D2:D233)} -> 590000 | C25: {=SUMPRODUCT(('VENTAS TOTALES 2026 v2'!J2:J233="ACCESORIOS")*'VENTAS TOTALES 2026 v2'!E2:E233)*$B$2} -> 0 | D25: =B25+C25 -> 590000 | E25: =IF($D$26=0,"",D25/$D$26) -> 0.00037174921
A26: TOTAL | B26: =SUM(B22:B25) -> 1260466450 | C26: =SUM(C22:C25) -> 326625000 | D26: =SUM(D22:D25) -> 1587091450 | E26: =SUM(E22:E25) -> 1
A28: VENTAS POR VENDEDOR
A29: VENDEDOR | B29: VENTAS GS | C29: VENTAS USD (en GS) | D29: TOTAL (GS) | E29: Nº FACTURAS | F29: % DEL TOTAL
A30: ALBERTO | B30: {=SUMPRODUCT(('VENTAS TOTALES 2026 v2'!G2:G233="ALBERTO")*('VENTAS TOTALES 2026 v2'!I2:I233<>"N/A")*'VENTAS TOTALES 2026 v2'!D2:D233)} -> 567208450 | C30: {=SUMPRODUCT(('VENTAS TOTALES 2026 v2'!G2:G233="ALBERTO")*('VENTAS TOTALES 2026 v2'!I2:I233<>"N/A")*'VENTAS TOTALES 2026 v2'!E2:E233)*$B$2} -> 315325000 | D30: =B30+C30 -> 882533450 | E30: =COUNTIFS('VENTAS TOTALES 2026 v2'!G2:G233,"ALBERTO",'VENTAS TOTALES 2026 v2'!I2:I233,"<>N/A") -> 76 | F30: =IF($D$33=0,"",D30/$D$33) -> 0.56005727
A31: MAURO | B31: {=SUMPRODUCT(('VENTAS TOTALES 2026 v2'!G2:G233="MAURO")*('VENTAS TOTALES 2026 v2'!I2:I233<>"N/A")*'VENTAS TOTALES 2026 v2'!D2:D233)} -> 693258000 | C31: {=SUMPRODUCT(('VENTAS TOTALES 2026 v2'!G2:G233="MAURO")*('VENTAS TOTALES 2026 v2'!I2:I233<>"N/A")*'VENTAS TOTALES 2026 v2'!E2:E233)*$B$2} -> 0 | D31: =B31+C31 -> 693258000 | E31: =COUNTIFS('VENTAS TOTALES 2026 v2'!G2:G233,"MAURO",'VENTAS TOTALES 2026 v2'!I2:I233,"<>N/A") -> 119 | F31: =IF($D$33=0,"",D31/$D$33) -> 0.43994273
A32: JAVIER | B32: {=SUMPRODUCT(('VENTAS TOTALES 2026 v2'!G2:G233="JAVIER")*('VENTAS TOTALES 2026 v2'!I2:I233<>"N/A")*'VENTAS TOTALES 2026 v2'!D2:D233)} -> 0 | C32: {=SUMPRODUCT(('VENTAS TOTALES 2026 v2'!G2:G233="JAVIER")*('VENTAS TOTALES 2026 v2'!I2:I233<>"N/A")*'VENTAS TOTALES 2026 v2'!E2:E233)*$B$2} -> 0 | D32: =B32+C32 -> 0 | E32: =COUNTIFS('VENTAS TOTALES 2026 v2'!G2:G233,"JAVIER",'VENTAS TOTALES 2026 v2'!I2:I233,"<>N/A") -> 0 | F32: =IF($D$33=0,"",D32/$D$33) -> 0
A33: TOTAL | B33: =SUM(B30:B32) -> 1260466450 | C33: =SUM(C30:C32) -> 315325000 | D33: =SUM(D30:D32) -> 1575791450 | E33: =SUM(E30:E32) -> 195 | F33: =SUM(F30:F32) -> 1
A35: TOP 15 CLIENTES POR FACTURACIÓN
A36: # | B36: CLIENTE | C36: TOTAL (GS) | D36: Nº FACTURAS | E36: % DEL TOTAL
A37: 1 | B37: LUAN DEPORTES S.A | C37: 186687500 | D37: 11 | E37: =C37/$C$52 -> 0.16551111
A38: 2 | B38: BRUPO VARGAS S.R.L | C38: 139937500 | D38: 1 | E38: =C38/$C$52 -> 0.12406407
A39: 3 | B39: DRUID SPORT E.A.S | C39: 127079000 | D39: 2 | E39: =C39/$C$52 -> 0.11266414
A40: 4 | B40: ANGEL GODOY | C40: 67290000 | D40: 1 | E40: =C40/$C$52 -> 0.05965714
A41: 5 | B41: FATIMA CASTILLO | C41: 65800000 | D41: 1 | E41: =C41/$C$52 -> 0.058336154
A42: 6 | B42: REINA BENITEZ | C42: 65490000 | D42: 2 | E42: =C42/$C$52 -> 0.058061318
A43: 7 | B43: TECNOTEXTIL E.A.S | C43: 59986000 | D43: 6 | E43: =C43/$C$52 -> 0.05318165
A44: 8 | B44: MARIO BAEZ | C44: 56050000 | D44: 1 | E44: =C44/$C$52 -> 0.049692119
A45: 9 | B45: DERLIS SALINAS | C45: 53800000 | D45: 1 | E45: =C45/$C$52 -> 0.047697342
...

Sheet LISTA_PRECIOS_SOLPRO
A1: Column1 | B1: Column2 | C1: Column3 | D1: Column4 | E1: Column5 | F1: Column6
A2: ID REF | B2: LÍNEA | C2: PRODUCTO | D2: P. CONTADO | E2: P. DIGITAL (QR) | F2: P. CRÉDITO
A3: IM-001 | B3: INDUSTRIAL | C3: HORNO TUCANO DTF 90CM FOB | D3: U$D 5.190 | E3: U$D 5.390 | F3: Gs. 33.890.000
A4: SC-001 | B4: COMERCIAL | C4: IMPRESORA EPSON F170 | D4: Gs. 2.590.000 | E4: Gs. 2.690.000 | F4: CONTADO
A5: SC-002 | B5: COMERCIAL | C5: IMPRESORA EPSON L121 | D5: Gs. 690.000 | E5: Gs. 690.000 | F5: CONTADO
A6: SC-003 | B6: COMERCIAL | C6: IMPRESORA EPSON L1250 | D6: Gs. 1.190.000 | E6: Gs. 1.190.000 | F6: CONTADO
A7: SC-004 | B7: COMERCIAL | C7: IMPRESORA EPSON L14150 | D7: Gs. 5.490.000 | E7: Gs. 5.690.000 | F7: CONTADO
A8: SC-005 | B8: COMERCIAL | C8: IMPRESORA EPSON L3210 | D8: Gs. 1.390.000 | E8: Gs. 1.390.000 | F8: CONTADO
A9: SC-006 | B9: COMERCIAL | C9: MP EPSON L 4360 MULTIFUNCION WIR | D9: Gs. 2.190.000 | E9: Gs. 2.290.000 | F9: CONTADO
A10: SC-007 | B10: COMERCIAL | C10: IMP EPSON L 3210 MULTIFUNCION | D10: Gs. 1.690.000 | E10: Gs. 1.790.000 | F10: CONTADO
A11: SC-008 | B11: COMERCIAL | C11: IMP EPSON L 3560 MULTIFUNCION WIR | D11: Gs. 1.990.000 | E11: Gs. 2.090.000 | F11: CONTADO
A12: SC-009 | B12: COMERCIAL | C12: IMP EPSON L 4260 MULTIFUNCION WIR | D12: Gs. 2.190.000 | E12: Gs. 2.290.000 | F12: CONTADO
... A189: CMB-029 | B189: COMERCIAL | C189: COMBO: GRABADORA LASER 10W + PATITAS BASE + EJE ROTATIVO ESTANDAR + COMPRESOR DE AIRE + CAMEO 5 | D189: Gs. 12.290.000 | E189: Gs. 12.790.000 | F189: CONTADO

Sheet VENTAS TOTALES 2026
A1: FECHA | B1: DESCRIPCION | C1: CLIENTE | D1: PRECIO GS | E1: PRECIO USD | F1: NRO_FACTURA | G1: VENDEDOR | H1: FORMA PAGO
A2: 05-01-2026 | B2: 1 TINTA CYAN S40600 | C2: WIDMER GRAPHIC | D2: 985000 | F2: 268 | G2: ALBERTO | H2: TRANS
A3: 05-01-2026 | B3: 2 TINTAS CYAN, 2 MAGENTA, 2 YELLOW F6470 | C3: TECNOTEXTIL E.A.S | D3: 5292000 | F3: 269 | G3: ALBERTO | H3: TRANS
A4: 05-01-2026 | B4: 4 TINTAS F9470, CYAN, MAGENTA, YELLOW, HDK | C4: JESSI LENS S.R.L | D4: 2180000 | F4: 270 | G4: ALBERTO | H4: TRANS
A5: 05-01-2026 | B5: 2 TINTAS YELLOW, 1 CYAN, 1 HDK F10070 | C5: LUAN DEPORTES S.A | E5: 1808 | F5: 271 | G5: ALBERTO | H5: TRANS
A6: 06-01-2026 | B6: 1 ACEPTACION DE PAGO | C6: EPSON ARGENTINA | E6: 6850.19 | F6: 272 | G6: JAVIER
A7: 08-01-2026 | B7: 2 TINTAS CYAN F10070 | C7: GRUPO UTEX E.A.S | D7: 6051000 | F7: 273 | G7: ALBERTO | H7: TRANS
A8: 08-01-2026 | B8: 1 TINTA MAGENTA S40600 | C8: JUAN RAMON ROMAN | D8: 985000 | F8: 274 | G8: ALBERTO | H8: TRANS
A9: 08-01-2026 | B9: 6 TINTAS CYAN, 8 YELLOW F6470 | C9: TECNOTEXTIL E.A.S | D9: 12348000 | F9: 275 | G9: ALBERTO | H9: TRANS
A10: 09-01-2026 | B10: 1 TINTA EPSON HDK F6470 | C10: DIVINO NIÑO | D10: 550000 | F10: 276 | G10: MAURO | H10: EFECTIVO
A11: 09-01-2026 | B11: 1 BORDADORA BROTHER PR680 | C11: REINA BENITEZ | D11: 57590000 | F11: 277 | G11: MAURO | H11: DEPOSITO
B12: ANULADO | C12: ANULADO | F12: 278
B13: ANULADO | C13: ANULADO | F13: 279
A14: 09-01-2026 | B14: COMBO F170+15EN1+CAMEO5 | C14: DIEGO BORDON | D14: 9590000 | F14: 280 | G14: MAURO | H14: TRANS
A15: 12-01-2026 | B15: LASER DE 20W COMPLETO | C15: REINA BENITEZ | D15: 7900000 | F15: 281 | G15: MAURO | H15: DEPOSITO
A16: 12-01-2026 | B16: 2 TINTAS YELLOW, 2 CYAN, 1 WIPWE F10070 | C16: LUAN DEPORTES S.A | E16: 2298 | F16: 282 | G16: ALBERTO | H16: TRANS
A17: 12-01-2026 | B17: 1 TINTA CYAN F6470 | C17: MIRTHA ELIZABETH | D17: 995000 | F17: 283 | G17: MAURO | H17: TRANS
A18: 12-01-2026 | B18: SPIFF POR VENTA DE F6470 | C18: EPSON ARGENTINA | E18: 1400 | F18: 284
A19: 12-01-2026 | B19: 4 TINTAS MAGENTA F6470 | C19: TECNOTEXTIL E.A.S | D19: 3528000 | F19: 285 | G19: ALBERTO | H19: TRANS
A20: 12-01-2026 | B20: 4 TINTAS CYAN, 2 YELLOW F6470 | C20: EVELYN MARTINEZ | D20: 4320000 | F20: 286 | G20: ALBERTO | H20: TRANS
A21: 13-01-2026 | B21: 1 TINTA NEGRO, 1 TINTA MAGENTA F6470 | C21: EUCLIDES JABIER VERA | D21: 1990000 | F21: 287 | G21: MAURO | H21: TRANS
A22: 13-01-2026 | B22: 1 COMBO L1250+8EN1 | C22: GABRIELA SALGUEIRO | D22: 3990000 | F22: 288 | G22: MAURO | H22: TRANS
A23: 13-01-2026 | B23: COMBO F170+8EN1 | C23: PASCUALA DAVALOS | D23: 5190000 | F23: 289 | G23: MAURO | H23: EFECTIVO
A24: 13-01-2026 | B24: 1 TINTA CYAN F6470 | C24: OSVAL JIMENEZ | D24: 939000 | F24: 290 | G24: ALBERTO | H24: TRANS
A25: 15-01-2026 | B25: 2 TINTAS EPSON HDK F6370 | C25: ROBERTO DUTRA | D25: 1080000 | F25: 291 | G25: ALBERTO
A26: 16-01-2026 | B26: SERVICIO TECNICO | C26: LUAN DEPORTES S.A | D26: 1500000 | F26: 292 | G26: JAVIER
A27: 16-01-2026 | B27: 1 EPSON F170 | C27: ANGEL ALMADA | D27: 2890000 | F27: 293 | G27: MAURO | H27: TRANS
A28: 16-01-2026 | B28: 1 JUEGO DE TINTA F6470 | C28: ALCIDES VALDEZ | D28: 3160000 | F28: 294 | G28: ALBERTO | H28: TRANS
A29: 16-01-2026 | B29: 3 TINTAS YELLOW F10070 | C29: LUAN DEPORTES S.A | E29: 1356 | F29: 295 | G29: ALBERTO | H29: TRANS
A30: 19-01-2026 | B30: 1 COMBO F170+8EN1 | C30: HUGO RENE GARAY | D30: 5190000 | F30: 296 | G30: MAURO | H30: TRANS
A31: 19-01-2026 | B31: 1 COMBO L121+11EN1 | C31: OSCAR SAMUDIO | D31: 4590000 | F31: 297 | G31: MAURO | H31: TRANS
A32: 19-01-2026 | B32: 1 COMBO DE F170+11EN1+LASER 20W COMPELTO | C32: NAYELI LEDESMA | D32: 13850000 | F32: 298 | G32: MAURO | H32: EFECTIVO
A33: 19-01-2026 | B33: 1 TINTA CYAN, 1 MAGENTA, 1 HDK F6470 | C33: ARNALDO CORONEL | D33: 2370000 | F33: 299 | G33: MAURO | H33: TRANS
A34: 20-01-2026 | B34: 2 TINTAS CYAN, 1 MAGENTA, 1 HDK F6470 | C34: GRUPO VIBER E.A.S | D34: 3160000 | F34: 301 | G34: ALBERTO | H34: TRANS
A35: 21-01-2026 | B35: 1 CAJA DE MANTENIMIENTO F170 | C35: DAIANA ALBINO | D35: 199000 | F35: 302 | G35: MAURO | H35: TRANS
A36: 21-01-2026 | B36: 1 COMBO L121+8EN1 | C36: LUIS CASCO | D36: 3290000 | F36: 303 | G36: MAURO | H36: TRANS
A37: 21-01-2026 | B37: 1 COMBO F170+11EN1+LASER DE 20W | C37: CARLOS FERREIRA | D37: 12080000 | F37: 304 | G37: MAURO | H37: EFECTIVO
A38: 21-01-2026 | B38: 3 TINTAS F6470, CYAN, MAGENTA, HDK | C38: CYV COMPANY E.A.S | D38: 2370000 | F38: 305 | G38: ALBERTO | H38: TRANS
A39: 21-01-2026 | B39: 1 CAJA F170 | C39: LUJAN FERNANDEZ | D39: 199000 | F39: 306 | G39: MAURO | H39: TRANS
A40: 21-01-2026 | B40: 1 8 EN 1 | C40: ANGEL BAUMANN | D40: 2590000 | F40: 307 | G40: MAURO | H40: TRANS
...

Sheet COSTOS_INTERNOS_SOLPRO
A1: ID | B1: PRODUCTO | C1: LINEA | D1: COSTO_ORIGINAL | E1: MONEDA
A2: SC-001 | B2: IMPRESORA EPSON F170 | C2: COMERCIAL | D2: 3000 | E2: USD
A3: SC-002 | B3: IMPRESORA EPSON L1250 | C3: COMERCIAL | D3: 1862 | E3: USD
A4: SC-003 | B4: IMPRESORA EPSON L121 | C4: COMERCIAL | D4: 1350 | E4: USD
A5: SC-004 | B5: IMPRESORA EPSON L8180 A3 | C5: COMERCIAL | D5: 6150 | E5: USD
A6: SC-005 | B6: BORDADORA BROTHER NV970LPA 2 EN 1 BORDA Y COSE 10 | C6: COMERCIAL | D6: 7400 | E6: USD
A7: SC-006 | B7: BORDADORA BROTHER PE560LPA 10X10 | C7: COMERCIAL | D7: 5250 | E7: USD
A8: SC-007 | B8: BORDADORA BROTHER PE910LPA 13X18 | C8: COMERCIAL | D8: 8500 | E8: USD
A9: SC-008 | B9: BORDADORA BROTHER BP1530LPA 16X26 | C9: COMERCIAL | D9: 11500 | E9: USD
A10: SC-009 | B10: BORDADORA BROTHER BP2150LPA 20X30 | C10: COMERCIAL | D10: 21500 | E10: USD
A11: SC-010 | B11: BORDADORA BROTHER BP3700LPA 24X36 | C11: COMERCIAL | D11: 34500 | E11: USD
A12: SC-011 | B12: BORDADORA BROTHER BE800LPA 13X18 | C12: COMERCIAL | D12: 8150 | E12: USD
A13: SC-012 | B13: BORDADORA BROTHER BE815LPA 13X18 | C13: COMERCIAL | D13: 8150 | E13: USD
... A157: TC-047 | B157: MAQUINA DE COSER COLLARETA IND WILPEX | C157: INDUSTRIAL | D157: 41000000 | E157: GS

Sheet VENTAS TOTALES 2026 v2
A1: FECHA | B1: DESCRIPCION | C1: CLIENTE | D1: PRECIO GS | E1: PRECIO USD | F1: NRO_FACTURA | G1: VENDEDOR | H1: FORMA PAGO | I1: COD_PRODUCTO | J1: LINEA
A2: 46143 | B2: 1 TINTA CYAN S40600 | C2: WIDMER GRAPHIC | D2: 985000 | F2: 268 | G2: ALBERTO | H2: TRANS | I2: SC-102 | J2: INSUMOS
A3: 46143 | B3: 2 TINTAS CYAN, 2 MAGENTA, 2 YELLOW F6470 | C3: TECNOTEXTIL E.A.S | D3: 5292000 | F3: 269 | G3: ALBERTO | H3: TRANS | I3: SC-102 | J3: INSUMOS
A4: 46143 | B4: 4 TINTAS F9470, CYAN, MAGENTA, YELLOW, HDK | C4: JESSI LENS S.R.L | D4: 2180000 | F4: 270 | G4: ALBERTO | H4: TRANS | I4: SC-108 | J4: INSUMOS
A5: 46143 | B5: 2 TINTAS YELLOW, 1 CYAN, 1 HDK F10070 | C5: LUAN DEPORTES S.A | E5: 1808 | F5: 271 | G5: ALBERTO | H5: TRANS | I5: SC-102 | J5: INSUMOS
A6: 46174 | B6: 1 ACEPTACION DE PAGO | C6: EPSON ARGENTINA | E6: 6850.19 | F6: 272 | G6: JAVIER | I6: N/A | J6: N/A
A7: 46235 | B7: 2 TINTAS CYAN F10070 | C7: GRUPO UTEX E.A.S | D7: 6051000 | F7: 273 | G7: ALBERTO | H7: TRANS | I7: SC-102 | J7: INSUMOS
A8: 46235 | B8: 1 TINTA MAGENTA S40600 | C8: JUAN RAMON ROMAN | D8: 985000 | F8: 274 | G8: ALBERTO | H8: TRANS | I8: SC-102 | J8: INSUMOS
A9: 46235 | B9: 6 TINTAS CYAN, 8 YELLOW F6470 | C9: TECNOTEXTIL E.A.S | D9: 12348000 | F9: 275 | G9: ALBERTO | H9: TRANS | I9: SC-102 | J9: INSUMOS
A10: 46266 | B10: 1 TINTA EPSON HDK F6470 | C10: DIVINO NIÑO | D10: 550000 | F10: 276 | G10: MAURO | H10: EFECTIVO | I10: SC-102 | J10: INSUMOS
A11: 46266 | B11: 1 BORDADORA BROTHER PR680 | C11: REINA BENITEZ | D11: 57590000 | F11: 277 | G11: MAURO | H11: DEPOSITO | I11: SC-024 | J11: COMERCIAL
B12: ANULADO | C12: ANULADO | F12: 278 | I12: N/A | J12: N/A
B13: ANULADO | C13: ANULADO | F13: 279 | I13: N/A | J13: N/A
A14: 13-01-2026 | B14: COMBO F170+15EN1+CAMEO5 | C14: DIEGO BORDON | D14: 9590000 | F14: 280 | G14: MAURO | H14: TRANS | I14: CMB-025 | J14: COMERCIAL
A15: 46357 | B15: LASER DE 20W COMPLETO | C15: REINA BENITEZ | D15: 7900000 | F15: 281 | G15: MAURO | H15: DEPOSITO | I15: TC-005 | J15: COMERCIAL
A16: 46357 | B16: 2 TINTAS YELLOW, 2 CYAN, 1 WIPWE F10070 | C16: LUAN DEPORTES S.A | E16: 2298 | F16: 282 | G16: ALBERTO | H16: TRANS | I16: SC-102 | J16: INSUMOS
A17: 46357 | B17: 1 TINTA CYAN F6470 | C17: MIRTHA ELIZABETH | D17: 995000 | F17: 283 | G17: MAURO | H17: TRANS | I17: SC-102 | J17: INSUMOS
A18: 46357 | B18: SPIFF POR VENTA DE F6470 | C18: EPSON ARGENTINA | E18: 1400 | F18: 284 | I18: N/A | J18: N/A
A19: 46357 | B19: 4 TINTAS MAGENTA F6470 | C19: TECNOTEXTIL E.A.S | D19: 3528000 | F19: 285 | G19: ALBERTO | H19: TRANS | I19: SC-102 | J19: INSUMOS
A20: 46357 | B20: 4 TINTAS CYAN, 2 YELLOW F6470 | C20: EVELYN MARTINEZ | D20: 4320000 | F20: 286 | G20: ALBERTO | H20: TRANS | I20: SC-102 | J20: INSUMOS
A21: 13-01-2026 | B21: 1 TINTA NEGRO, 1 TINTA MAGENTA F6470 | C21: EUCLIDES JABIER VERA | D21: 1990000 | F21: 287 | G21: MAURO | H21: TRANS | I21: SC-102 | J21: INSUMOS
A22: 13-01-2026 | B22: 1 COMBO L1250+8EN1 | C22: GABRIELA SALGUEIRO | D22: 3990000 | F22: 288 | G22: MAURO | H22: TRANS | I22: CMB-011 | J22: COMERCIAL
A23: 13-01-2026 | B23: COMBO F170+8EN1 | C23: PASCUALA DAVALOS | D23: 5190000 | F23: 289 | G23: MAURO | H23: EFECTIVO | I23: CMB-002 | J23: COMERCIAL
A24: 13-01-2026 | B24: 1 TINTA CYAN F6470 | C24: OSVAL JIMENEZ | D24: 939000 | F24: 290 | G24: ALBERTO | H24: TRANS | I24: SC-102 | J24: INSUMOS
A25: 15-01-2026 | B25: 2 TINTAS EPSON HDK F6370 | C25: ROBERTO DUTRA | D25: 1080000 | F25: 291 | G25: ALBERTO | I25: SC-108 | J25: INSUMOS
A26: 16-01-2026 | B26: SERVICIO TECNICO | C26: LUAN DEPORTES S.A | D26: 1500000 | F26: 292 | G26: JAVIER | I26: N/A | J26: N/A
A27: 16-01-2026 | B27: 1 EPSON F170 | C27: ANGEL ALMADA | D27: 2890000 | F27: 293 | G27: MAURO | H27: TRANS | I27: SC-001 | J27: COMERCIAL
A28: 16-01-2026 | B28: 1 JUEGO DE TINTA F6470 | C28: ALCIDES VALDEZ | D28: 3160000 | F28: 294 | G28: ALBERTO | H28: TRANS | I28: SC-102 | J28: INSUMOS
A29: 16-01-2026 | B29: 3 TINTAS YELLOW F10070 | C29: LUAN DEPORTES S.A | E29: 1356 | F29: 295 | G29: ALBERTO | H29: TRANS | I29: SC-102 | J29: INSUMOS
A30: 19-01-2026 | B30: 1 COMBO F170+8EN1 | C30: HUGO RENE GARAY | D30: 5190000 | F30: 296 | G30: MAURO | H30: TRANS | I30: CMB-002 | J30: COMERCIAL
A31: 19-01-2026 | B31: 1 COMBO L121+11EN1 | C31: OSCAR SAMUDIO | D31: 4590000 | F31: 297 | G31: MAURO | H31: TRANS | I31: CMB-016 | J31: COMERCIAL
A32: 19-01-2026 | B32: 1 COMBO DE F170+11EN1+LASER 20W COMPELTO | C32: NAYELI LEDESMA | D32: 13850000 | F32: 298 | G32: MAURO | H32: EFECTIVO | I32: CMB-026 | J32: COMERCIAL
A33: 19-01-2026 | B33: 1 TINTA CYAN, 1 MAGENTA, 1 HDK F6470 | C33: ARNALDO CORONEL | D33: 2370000 | F33: 299 | G33: MAURO | H33: TRANS | I33: SC-102 | J33: INSUMOS
A34: 20-01-2026 | B34: 2 TINTAS CYAN, 1 MAGENTA, 1 HDK F6470 | C34: GRUPO VIBER E.A.S | D34: 3160000 | F34: 301 | G34: ALBERTO | H34: TRANS | I34: SC-102 | J34: INSUMOS
A35: 21-01-2026 | B35: 1 CAJA DE MANTENIMIENTO F170 | C35: DAIANA ALBINO | D35: 199000 | F35: 302 | G35: MAURO | H35: TRANS | I35: SC-103 | J35: INSUMOS
A36: 21-01-2026 | B36: 1 COMBO L121+8EN1 | C36: LUIS CASCO | D36: 3290000 | F36: 303 | G36: MAURO | H36: TRANS | I36: CMB-008 | J36: COMERCIAL
A37: 21-01-2026 | B37: 1 COMBO F170+11EN1+LASER DE 20W | C37: CARLOS FERREIRA | D37: 12080000 | F37: 304 | G37: MAURO | H37: EFECTIVO | I37: CMB-026 | J37: COMERCIAL
A38: 21-01-2026 | B38: 3 TINTAS F6470, CYAN, MAGENTA, HDK | C38: CYV COMPANY E.A.S | D38: 2370000 | F38: 305 | G38: ALBERTO | H38: TRANS | I38: SC-102 | J38: INSUMOS
A39: 21-01-2026 | B39: 1 CAJA F170 | C39: LUJAN FERNANDEZ | D39: 199000 | F39: 306 | G39: MAURO | H39: TRANS | I39: SC-103 | J39: INSUMOS
A40: 21-01-2026 | B40: 1 8 EN 1 | C40: ANGEL BAUMANN | D40: 2590000 | F40: 307 | G40: MAURO | H40: TRANS | I40: TC-012 | J40: COMERCIAL
...
